[2025-07-25T07:00:01.625+0000] {local_task_job_runner.py:123} INFO - ::group::Pre task execution logs
[2025-07-25T07:00:01.646+0000] {taskinstance.py:2613} INFO - Dependencies all met for dep_context=non-requeueable deps ti=<TaskInstance: etl_postgres.create_tables scheduled__2025-07-25T06:00:00+00:00 [queued]>
[2025-07-25T07:00:01.656+0000] {taskinstance.py:2613} INFO - Dependencies all met for dep_context=requeueable deps ti=<TaskInstance: etl_postgres.create_tables scheduled__2025-07-25T06:00:00+00:00 [queued]>
[2025-07-25T07:00:01.657+0000] {taskinstance.py:2866} INFO - Starting attempt 1 of 6
[2025-07-25T07:00:01.672+0000] {taskinstance.py:2889} INFO - Executing <Task(PostgresOperator): create_tables> on 2025-07-25 06:00:00+00:00
[2025-07-25T07:00:01.681+0000] {standard_task_runner.py:104} INFO - Running: ['***', 'tasks', 'run', 'etl_postgres', 'create_tables', 'scheduled__2025-07-25T06:00:00+00:00', '--job-id', '176', '--raw', '--subdir', 'DAGS_FOLDER/etl_dag.py', '--cfg-path', '/tmp/tmpoxwsvfb8']
[2025-07-25T07:00:01.688+0000] {standard_task_runner.py:105} INFO - Job 176: Subtask create_tables
[2025-07-25T07:00:01.688+0000] {logging_mixin.py:190} WARNING - /home/***/.local/lib/python3.12/site-packages/***/task/task_runner/standard_task_runner.py:70 DeprecationWarning: This process (pid=11472) is multi-threaded, use of fork() may lead to deadlocks in the child.
[2025-07-25T07:00:01.690+0000] {standard_task_runner.py:72} INFO - Started process 11473 to run task
[2025-07-25T07:00:01.782+0000] {task_command.py:467} INFO - Running <TaskInstance: etl_postgres.create_tables scheduled__2025-07-25T06:00:00+00:00 [running]> on host 0c6a6447a272
[2025-07-25T07:00:02.136+0000] {taskinstance.py:3132} INFO - Exporting env vars: AIRFLOW_CTX_DAG_OWNER='***' AIRFLOW_CTX_DAG_ID='etl_postgres' AIRFLOW_CTX_TASK_ID='create_tables' AIRFLOW_CTX_EXECUTION_DATE='2025-07-25T06:00:00+00:00' AIRFLOW_CTX_TRY_NUMBER='1' AIRFLOW_CTX_DAG_RUN_ID='scheduled__2025-07-25T06:00:00+00:00'
[2025-07-25T07:00:02.137+0000] {taskinstance.py:731} INFO - ::endgroup::
[2025-07-25T07:00:02.150+0000] {sql.py:278} INFO - Executing: CREATE TABLE IF NOT EXISTS public.artists (
	artistid varchar(256) NOT NULL,
	name varchar(256),
	location varchar(256),
	lattitude numeric(18,0),
	longitude numeric(18,0)
);

CREATE TABLE IF NOT EXISTS public.songplays (
	playid varchar(32) NOT NULL,
	start_time timestamp NOT NULL,
	userid int4 NOT NULL,
	"level" varchar(256),
	songid varchar(256),
	artistid varchar(256),
	sessionid int4,
	location varchar(256),
	user_agent varchar(256),
	CONSTRAINT songplays_pkey PRIMARY KEY (playid)
);

CREATE TABLE IF NOT EXISTS public.songs (
	songid varchar(256) NOT NULL,
	title varchar(256),
	artistid varchar(256),
	"year" int4,
	duration numeric(18,0),
	CONSTRAINT songs_pkey PRIMARY KEY (songid)
);

CREATE TABLE IF NOT EXISTS public.staging_events (
	artist varchar(256),
	auth varchar(256),
	firstname varchar(256),
	gender varchar(256),
	iteminsession int4,
	lastname varchar(256),
	length numeric(18,0),
	"level" varchar(256),
	location varchar(256),
	"method" varchar(256),
	page varchar(256),
	registration numeric(18,0),
	sessionid int4,
	song varchar(256),
	status int4,
	ts int8,
	useragent varchar(256),
	userid int4
);

CREATE TABLE IF NOT EXISTS public.staging_songs (
	num_songs int4,
	artist_id varchar(256),
	artist_name varchar(256),
	artist_latitude numeric(18,0),
	artist_longitude numeric(18,0),
	artist_location varchar(256),
	song_id varchar(256),
	title varchar(256),
	duration numeric(18,0),
	"year" int4
);

CREATE TABLE IF NOT EXISTS public."time" (
	start_time timestamp NOT NULL,
	"hour" int4,
	"day" int4,
	week int4,
	"month" varchar(256),
	"year" int4,
	weekday varchar(256),
	CONSTRAINT time_pkey PRIMARY KEY (start_time)
) ;

CREATE TABLE IF NOT EXISTS public.users (
	userid int4 NOT NULL,
	first_name varchar(256),
	last_name varchar(256),
	gender varchar(256),
	"level" varchar(256),
	CONSTRAINT users_pkey PRIMARY KEY (userid)
);
[2025-07-25T07:00:02.161+0000] {base.py:84} INFO - Retrieving connection '***_default'
[2025-07-25T07:00:02.169+0000] {base.py:84} INFO - Retrieving connection '***_default'
[2025-07-25T07:00:02.172+0000] {taskinstance.py:3311} ERROR - Task failed with exception
Traceback (most recent call last):
  File "/home/airflow/.local/lib/python3.12/site-packages/airflow/models/taskinstance.py", line 767, in _execute_task
    result = _execute_callable(context=context, **execute_callable_kwargs)
             ^^^^^^^^^^^^^^^^^^^^^^^^^^^^^^^^^^^^^^^^^^^^^^^^^^^^^^^^^^^^^
  File "/home/airflow/.local/lib/python3.12/site-packages/airflow/models/taskinstance.py", line 733, in _execute_callable
    return ExecutionCallableRunner(
           ^^^^^^^^^^^^^^^^^^^^^^^^
  File "/home/airflow/.local/lib/python3.12/site-packages/airflow/utils/operator_helpers.py", line 252, in run
    return self.func(*args, **kwargs)
           ^^^^^^^^^^^^^^^^^^^^^^^^^^
  File "/home/airflow/.local/lib/python3.12/site-packages/airflow/models/baseoperator.py", line 417, in wrapper
    return func(self, *args, **kwargs)
           ^^^^^^^^^^^^^^^^^^^^^^^^^^^
  File "/home/airflow/.local/lib/python3.12/site-packages/airflow/providers/common/sql/operators/sql.py", line 284, in execute
    output = hook.run(
             ^^^^^^^^^
  File "/home/airflow/.local/lib/python3.12/site-packages/airflow/providers/common/sql/hooks/sql.py", line 485, in run
    with self._create_autocommit_connection(autocommit) as conn:
         ^^^^^^^^^^^^^^^^^^^^^^^^^^^^^^^^^^^^^^^^^^^^^^
  File "/usr/local/lib/python3.12/contextlib.py", line 137, in __enter__
    return next(self.gen)
           ^^^^^^^^^^^^^^
  File "/home/airflow/.local/lib/python3.12/site-packages/airflow/providers/common/sql/hooks/sql.py", line 609, in _create_autocommit_connection
    with closing(self.get_conn()) as conn:
                 ^^^^^^^^^^^^^^^
  File "/home/airflow/.local/lib/python3.12/site-packages/airflow/providers/postgres/hooks/postgres.py", line 181, in get_conn
    self.conn = psycopg2.connect(**conn_args)
                ^^^^^^^^^^^^^^^^^^^^^^^^^^^^^
  File "/home/airflow/.local/lib/python3.12/site-packages/psycopg2/__init__.py", line 122, in connect
    conn = _connect(dsn, connection_factory=connection_factory, **kwasync)
           ^^^^^^^^^^^^^^^^^^^^^^^^^^^^^^^^^^^^^^^^^^^^^^^^^^^^^^^^^^^^^^^
psycopg2.OperationalError: connection to server at "***" (172.18.0.2), port 5432 failed: FATAL:  password authentication failed for user "***"

[2025-07-25T07:00:02.183+0000] {taskinstance.py:1225} INFO - Marking task as UP_FOR_RETRY. dag_id=etl_***, task_id=create_tables, run_id=scheduled__2025-07-25T06:00:00+00:00, execution_date=20250725T060000, start_date=20250725T070001, end_date=20250725T070002
[2025-07-25T07:00:02.194+0000] {taskinstance.py:340} INFO - ::group::Post task execution logs
[2025-07-25T07:00:02.195+0000] {standard_task_runner.py:124} ERROR - Failed to execute job 176 for task create_tables (connection to server at "***" (172.18.0.2), port 5432 failed: FATAL:  password authentication failed for user "***"
; 11473)
Traceback (most recent call last):
  File "/home/airflow/.local/lib/python3.12/site-packages/airflow/task/task_runner/standard_task_runner.py", line 117, in _start_by_fork
    ret = args.func(args, dag=self.dag)
          ^^^^^^^^^^^^^^^^^^^^^^^^^^^^^
  File "/home/airflow/.local/lib/python3.12/site-packages/airflow/cli/cli_config.py", line 49, in command
    return func(*args, **kwargs)
           ^^^^^^^^^^^^^^^^^^^^^
  File "/home/airflow/.local/lib/python3.12/site-packages/airflow/utils/cli.py", line 116, in wrapper
    return f(*args, **kwargs)
           ^^^^^^^^^^^^^^^^^^
  File "/home/airflow/.local/lib/python3.12/site-packages/airflow/cli/commands/task_command.py", line 483, in task_run
    task_return_code = _run_task_by_selected_method(args, _dag, ti)
                       ^^^^^^^^^^^^^^^^^^^^^^^^^^^^^^^^^^^^^^^^^^^^
  File "/home/airflow/.local/lib/python3.12/site-packages/airflow/cli/commands/task_command.py", line 256, in _run_task_by_selected_method
    return _run_raw_task(args, ti)
           ^^^^^^^^^^^^^^^^^^^^^^^
  File "/home/airflow/.local/lib/python3.12/site-packages/airflow/cli/commands/task_command.py", line 341, in _run_raw_task
    return ti._run_raw_task(
           ^^^^^^^^^^^^^^^^^
  File "/home/airflow/.local/lib/python3.12/site-packages/airflow/utils/session.py", line 97, in wrapper
    return func(*args, session=session, **kwargs)
           ^^^^^^^^^^^^^^^^^^^^^^^^^^^^^^^^^^^^^^
  File "/home/airflow/.local/lib/python3.12/site-packages/airflow/models/taskinstance.py", line 3005, in _run_raw_task
    return _run_raw_task(
           ^^^^^^^^^^^^^^
  File "/home/airflow/.local/lib/python3.12/site-packages/airflow/models/taskinstance.py", line 273, in _run_raw_task
    TaskInstance._execute_task_with_callbacks(
  File "/home/airflow/.local/lib/python3.12/site-packages/airflow/models/taskinstance.py", line 3159, in _execute_task_with_callbacks
    result = self._execute_task(context, task_orig)
             ^^^^^^^^^^^^^^^^^^^^^^^^^^^^^^^^^^^^^^
  File "/home/airflow/.local/lib/python3.12/site-packages/airflow/models/taskinstance.py", line 3183, in _execute_task
    return _execute_task(self, context, task_orig)
           ^^^^^^^^^^^^^^^^^^^^^^^^^^^^^^^^^^^^^^^
  File "/home/airflow/.local/lib/python3.12/site-packages/airflow/models/taskinstance.py", line 767, in _execute_task
    result = _execute_callable(context=context, **execute_callable_kwargs)
             ^^^^^^^^^^^^^^^^^^^^^^^^^^^^^^^^^^^^^^^^^^^^^^^^^^^^^^^^^^^^^
  File "/home/airflow/.local/lib/python3.12/site-packages/airflow/models/taskinstance.py", line 733, in _execute_callable
    return ExecutionCallableRunner(
           ^^^^^^^^^^^^^^^^^^^^^^^^
  File "/home/airflow/.local/lib/python3.12/site-packages/airflow/utils/operator_helpers.py", line 252, in run
    return self.func(*args, **kwargs)
           ^^^^^^^^^^^^^^^^^^^^^^^^^^
  File "/home/airflow/.local/lib/python3.12/site-packages/airflow/models/baseoperator.py", line 417, in wrapper
    return func(self, *args, **kwargs)
           ^^^^^^^^^^^^^^^^^^^^^^^^^^^
  File "/home/airflow/.local/lib/python3.12/site-packages/airflow/providers/common/sql/operators/sql.py", line 284, in execute
    output = hook.run(
             ^^^^^^^^^
  File "/home/airflow/.local/lib/python3.12/site-packages/airflow/providers/common/sql/hooks/sql.py", line 485, in run
    with self._create_autocommit_connection(autocommit) as conn:
         ^^^^^^^^^^^^^^^^^^^^^^^^^^^^^^^^^^^^^^^^^^^^^^
  File "/usr/local/lib/python3.12/contextlib.py", line 137, in __enter__
    return next(self.gen)
           ^^^^^^^^^^^^^^
  File "/home/airflow/.local/lib/python3.12/site-packages/airflow/providers/common/sql/hooks/sql.py", line 609, in _create_autocommit_connection
    with closing(self.get_conn()) as conn:
                 ^^^^^^^^^^^^^^^
  File "/home/airflow/.local/lib/python3.12/site-packages/airflow/providers/postgres/hooks/postgres.py", line 181, in get_conn
    self.conn = psycopg2.connect(**conn_args)
                ^^^^^^^^^^^^^^^^^^^^^^^^^^^^^
  File "/home/airflow/.local/lib/python3.12/site-packages/psycopg2/__init__.py", line 122, in connect
    conn = _connect(dsn, connection_factory=connection_factory, **kwasync)
           ^^^^^^^^^^^^^^^^^^^^^^^^^^^^^^^^^^^^^^^^^^^^^^^^^^^^^^^^^^^^^^^
psycopg2.OperationalError: connection to server at "***" (172.18.0.2), port 5432 failed: FATAL:  password authentication failed for user "***"

[2025-07-25T07:00:02.229+0000] {local_task_job_runner.py:266} INFO - Task exited with return code 1
[2025-07-25T07:00:02.246+0000] {taskinstance.py:3895} INFO - 0 downstream tasks scheduled from follow-on schedule check
[2025-07-25T07:00:02.248+0000] {local_task_job_runner.py:245} INFO - ::endgroup::
